Workbook

Sheet Ideas
A2: S.no | B2: Tasks | C2: Due date
A3: 1 | B3: Performance Tracking | C3: 05.08.2025
A4: 2 | B4: Deployment of Excess Cash on Books
A5: 3 | B5: New Strategies/Equities Deployment Plan
B6: a. Drawdown Deployment Plan for Equities
B7: b. Leverage using Gold and Equities: QAW at 2x
B8: c. Equity Futures using some leverage since margin is empty
B9: d. Consider tax numbers in all calculations
B10: e. Work Backwards: what needs to be done to make more
A11: 4 | B11: Working Capital Debt on Portfolio
A12: 5 | B12: Deployment in Nasdaq using broker dealer strucutre and grd
A13: 6 | B13: Open IB Tws USA account
A14: 7 | B14: Gold at 2x using Trend Following system
A15: 8 | B15: Equities at 2x using Trend Following System: 10 stock Momentum Portfolio

Sheet Balance Sheet RN
A2: Balance Sheet As on 30.06.2025
A3: S.no | B3: Particulars | C3: Category | D3: 30.06.2025 | F3: S.no | G3: Particulars | H3: Category | I3: 30.06.2025
A4: 1 | B4: Rishabh Nahar | C4: Equity | D4: =31920540+47157270-17646683+4440957-1985702 -> 63886382 | F4: 1 | G4: MCPL | H4: Investment | I4: 28950000
A5: =A4+1 -> 2 | B5: Ramesh Nahar | C5: Equity | D5: 113270120 | F5: =F4+1 -> 2 | G5: Zerodha Total RN | H5: Investment | I5: 44982541
A6: =A5+1 -> 3 | B6: Sushila Nahar | C6: Equity | D6: 41674608 | F6: =F5+1 -> 3 | G6: Zerodha Loaned MCPL | H6: Investment | I6: 189449437
A7: =A6+1 -> 4 | B7: Equity Loans | C7: Equity | D7: 80000000 | F7: =F6+1 -> 4 | G7: Zerodha Loan MCPL Eq | H7: Investment | I7: 16481200
A8: =A7+1 -> 5 | B8: Personal Loans | C8: Debt | D8: 0 | F8: =F7+1 -> 5 | G8: Qode Advisors LLP | H8: Investment | I8: 17500000
A9: =A8+1 -> 6 | B9: Current Year Profits RN | C9: Equity | D9: =-333918+265866 -> -68052 | F9: =F8+1 -> 6 | G9: Qode Securitites | I9: 2051670
A10: =A9+1 -> 7 | B10: Unrelealised Profits RN | C10: Equity | D10: =1692377+18866254 -> 20558631 | F10: =F9+1 -> 7 | G10: Rekha Kothari | H10: Investment | I10: 6750000
A11: =A10+1 -> 8 | B11: Swan | C11: Loan | D11: 6892535 | F11: =F10+1 -> 8 | G11: Sailesh Nahar | H11: Loan | I11: 150000
A12: =A11+1 -> 9 | B12: Less: Tax( SA + Advance) | D12: -7800000 | F12: =F11+1 -> 9 | G12: Qode Advisors PMS | H12: Investment | I12: 7000000
A13: =A12+1 -> 10 | B13: Yogita Gift | D13: -2550000 | F13: =F12+1 -> 10 | G13: Ware Innovations | I13: -158000
A14: 11 | B14: Jainam Nimai Loss | D14: -6113397
D21: =SUM(D4:D19) -> 309750827 | I21: =SUM(I4:I19) -> 313156848 | J21: =D21-I21 -> -3406021

Sheet Balance Sheet MCL
A2: Balance Sheet As on 30.06.2025
A3: S.no | B3: Particulars | C3: Category | D3: 30.06.2025 | F3: S.no | G3: Particulars | H3: Category | I3: 30.06.2025
A4: 1 | B4: Company Capital | C4: Equity | D4: =16588264+12257627-758271 -> 28087620 | F4: 1
A5: =A4+1 -> 2 | B5: Rishabh Nahar | C5: Loan Ac | D5: ='[1]Balance Sheet RN'!I4 -> 28950000 | F5: =F4+1 -> 2 | G5: Zerodha Total MCPL | H5: Investment | I5: =276135000-'[1]Balance Sheet RN'!I6-'[1]Balance Sheet RN'!I7 -> 70204363
A6: =A5+1 -> 3 | B6: Ramesh Nahar | C6: Capital | D6: 25000 | F6: =F5+1 -> 3 | G6: Aurus Alpha LLP | H6: Investment | I6: 44000000
A7: =A6+1 -> 4 | B7: Sushila Nahar | C7: Equity | D7: 25000 | F7: =F6+1 -> 4 | G7: SPF Debtors | I7: 2360000
A8: =A7+1 -> 5 | B8: Rishabh Nahar Capital | C8: Capital | D8: 50000 | F8: =F7+1 -> 5 | G8: Bank Balance
A9: =A8+1 -> 6 | B9: Personal Loans | C9: Debt | D9: 0 | F9: =F8+1 -> 6
A10: =A9+1 -> 7 | B10: Unrealised Profits MCL | C10: Equity | D10: 48000000 | F10: =F9+1 -> 7
A11: =A10+1 -> 8 | B11: Unrelealised Profits MCL | C11: Equity | D11: =1336905 -> 1336905 | F11: =F10+1 -> 8
A12: =A11+1 -> 9 | B12: Consultancy Income CY | C12: Equity | D12: 8000000 | F12: =F11+1 -> 9
A13: =A12+1 -> 10 | B13: Less: Tax( SA + Advance) | D13: =-2000000-1500000 -> -3500000 | F13: =F12+1 -> 10
A14: 11 | F14: 11
A15: 12 | F15: 12
D21: =SUM(D4:D19) -> 110974525 | I21: =SUM(I4:I19) -> 116564363 | K21: =I21-D21 -> 5589838
D26: =D21-D5 -> 82024525

Sheet Pivot
A1: Networth | F1: Equity / Debt / Gold Backed Debt / Cash | AE1: Portfolio Risk
A3: Liquidity | B3: ='Networth Inputs - old'!Q4 -> 8.9887254e+08 | C3: =B3/$B$5 -> 1.081191
A4: Less: Debt | B4: ='Networth Inputs - old'!Q5 -> 67500000 | C4: =B4/$B$5 -> 0.081191038
A5: Networth | B5: ='Networth Inputs - old'!Q6 -> 8.3137254e+08 | Z5: Assets Owned Directly/Indirectly | AE5: Equity | AJ5: Debt
Z7: Equity | AA7: =VLOOKUP("Equity",$P$3:$Q$9,2,FALSE) -> #N/A | AB7: =AA7/$AA$11 -> #N/A | AE7: Zerodha Broking RN: EQ Holdings | AF7: =VLOOKUP(AE7,'Networth Inputs - old'!$C$4:$E$53,3,FALSE) -> 86524104 | AG7: =AF7/$AF$18 -> #N/A | AJ7: Karan SPF | AK7: =VLOOKUP(AJ7,'Networth Inputs - old'!$C$4:$E$53,3,FALSE) -> #N/A | AL7: =AK7/$AK$26 -> #N/A
Z8: Debt | AE8: Zerodha Broking RN: EQ Mutual Funds | AF8: =VLOOKUP(AE8,'Networth Inputs - old'!$C$4:$E$53,3,FALSE) -> 0 | AG8: =AF8/$AF$18 -> #N/A | AJ8: Loan to Vihaan | AK8: =VLOOKUP(AJ8,'Networth Inputs - old'!$C$4:$E$53,3,FALSE) -> 3000000 | AL8: =AK8/$AK$26 -> #N/A
Z9: Gold - India | AA9: =17*100*97873 -> 166384100 | AB9: =AA9/$AA$11 -> #N/A | AE9: Zerodha Broking RN: Cash | AF9: =VLOOKUP(AE9,'Networth Inputs - old'!$C$4:$E$53,3,FALSE) -> 14852 | AG9: =AF9/$AF$18 -> #N/A | AJ9: Fancy Nahar Current Account | AK9: =VLOOKUP(AJ9,'Networth Inputs - old'!$C$4:$E$53,3,FALSE) -> #N/A | AL9: =AK9/$AK$26 -> #N/A
AE10: Zerodha Broking Mishayan: EQ Holdings | AF10: =VLOOKUP(AE10,'Networth Inputs - old'!$C$4:$E$53,3,FALSE) -> 24489026 | AG10: =AF10/$AF$18 -> #N/A | AJ10: Deepak Nahar Current Account - Qode | AK10: =VLOOKUP(AJ10,'Networth Inputs - old'!$C$4:$E$53,3,FALSE) -> #N/A | AL10: =AK10/$AK$26 -> #N/A
Z11: Total | AA11: =SUM(AA7:AA9) -> #N/A | AB11: =AA11/AA11 -> #N/A | AE11: Zerodha Broking Mishayan: EQ Mutual Fund | AF11: =VLOOKUP(AE11,'Networth Inputs - old'!$C$4:$E$53,3,FALSE) -> 2.9994569e+08 | AG11: =AF11/$AF$18 -> #N/A | AJ11: Aurus Alpha Deposit | AK11: =VLOOKUP(AJ11,'Networth Inputs - old'!$C$4:$E$53,3,FALSE) -> 31500000 | AL11: =AK11/$AK$26 -> #N/A
AE12: Sushila Nahar Equity MF | AF12: =VLOOKUP(AE12,'Networth Inputs - old'!$C$4:$E$53,3,FALSE) -> 15368350 | AG12: =AF12/$AF$18 -> #N/A | AJ12: Aurus Alpha FD Deposit | AK12: =VLOOKUP(AJ12,'Networth Inputs - old'!$C$4:$E$53,3,FALSE) -> #N/A | AL12: =AK12/$AK$26 -> #N/A
Z13: Leverage on Networth | AB13: =AA11/B5 -> #N/A | AE13: Yogita Agrawal QGF | AF13: =VLOOKUP(AE13,'Networth Inputs - old'!$C$4:$E$53,3,FALSE) -> #N/A | AG13: =AF13/$AF$18 -> #N/A | AJ13: Swan Capital | AK13: =VLOOKUP(AJ13,'Networth Inputs - old'!$C$4:$E$53,3,FALSE) -> 5881036 | AL13: =AK13/$AK$26 -> #N/A
Z14: Leverage on Liquidity | AB14: =AA11/B3 -> #N/A | AE14: PMS QFH Strategy | AF14: =VLOOKUP(AE14,'Networth Inputs - old'!$C$4:$E$53,3,FALSE) -> 6092676 | AG14: =AF14/$AF$18 -> #N/A | AJ14: HDFC Bank RN | AK14: =VLOOKUP(AJ14,'Networth Inputs - old'!$C$4:$E$53,3,FALSE) -> 1550293 | AL14: =AK14/$AK$26 -> #N/A
AJ15: HDFC Bank Mishayan | AK15: =VLOOKUP(AJ15,'Networth Inputs - old'!$C$4:$E$53,3,FALSE) -> 4287189 | AL15: =AK15/$AK$26 -> #N/A
AJ16: YG | AK16: =VLOOKUP(AJ16,'Networth Inputs - old'!$C$4:$E$53,3,FALSE) -> #N/A | AL16: =AK16/$AK$26 -> #N/A
AJ17: Interest Hand | AK17: =VLOOKUP(AJ17,'Networth Inputs - old'!$C$4:$E$53,3,FALSE) -> 0 | AL17: =AK17/$AK$26 -> #N/A
AE18: Total | AF18: =SUM(AF7:AF16) -> #N/A | AG18: =AF18/$AF$18 -> #N/A | AJ18: FD | AK18: =VLOOKUP(AJ18,'Networth Inputs - old'!$C$4:$E$53,3,FALSE) -> 23500000 | AL18: =AK18/$AK$26 -> #N/A
AJ19: Zerodha Broking Mishayan: Debt Mutual Fund | AK19: =VLOOKUP(AJ19,'Networth Inputs - old'!$C$4:$E$53,3,FALSE) -> 0 | AL19: =AK19/$AK$26 -> #N/A
AJ20: Zerodha Broking Mishayan: Liquidbees/ Liquidcase | AK20: =VLOOKUP(AJ20,'Networth Inputs - old'!$C$4:$E$53,3,FALSE) -> 0 | AL20: =AK20/$AK$26 -> #N/A
AE21: separate eq matrix because once we take other future exposure eg defence, it will be added here | AJ21: Zerodha Broking Mishayan: Cash | AK21: =VLOOKUP(AJ21,'Networth Inputs - old'!$C$4:$E$53,3,FALSE) -> 151543569 | AL21: =AK21/$AK$26 -> #N/A
AJ22: Gold India | AK22: =AA9 -> 166384100 | AL22: =AK22/$AK$26 -> #N/A
AJ26: Total | AK26: =SUM(AK7:AK24) -> #N/A | AL26: =AK26/$AK$26 -> #N/A
K30: Return Expectation | Q30: Risky Bets
T31: Other than this we have large cap mutual funds
Q32: Discretionary Stock | R32: =VLOOKUP(Q32,$F$27:$G$29,2,FALSE) -> #N/A | T32: worth 2 cr
K33: Particulars | L33: Exposure Values | M33: Expected Returns | N33: Profits | O33: % of total profit | Q33: % of Networth | R33: =R32/B5 -> #N/A
K34: Debt | L34: =GETPIVOTDATA("Total Value",Mastersheet!$AN$9,"Equity / Debt","Debt") -> 4.4792142e+08 | M34: 0.05 | N34: =M34*L34 -> 22396071 | O34: =N34/$N$45 -> #REF! | Q34: % of Liquidity | R34: =R32/B3 -> #N/A
K35: Equity | L35: =GETPIVOTDATA("Total Value",Mastersheet!$AN$9,"Equity / Debt","Equity") -> 3.204756e+08 | M35: 0.12 | N35: =M35*L35 -> 38457072 | O35: =N35/$N$45 -> #REF!
K36: =K4 -> 0 | L36: =GETPIVOTDATA("Total Exposure",$K$3,"Strategy Name","Gold") -> #REF! | M36: 0.06 | N36: =M36*L36 -> #REF! | O36: =N36/$N$45 -> #REF! | Q36: This should not be greater than 10%
K37: =K5 -> 0 | L37: =GETPIVOTDATA("Total Exposure",$K$3,"Strategy Name","Long Options") -> #REF! | M37: 0.04 | N37: =M37*L37 -> #REF! | O37: =N37/$N$45 -> #REF!
K38: =K6 -> 0 | L38: =GETPIVOTDATA("Total Exposure",$K$3,"Strategy Name","PSAR") -> #REF! | M38: 0.06 | N38: =M38*L38 -> #REF! | O38: =N38/$N$45 -> #REF!
K39: =K7 -> 0 | L39: =GETPIVOTDATA("Total Exposure",$K$3,"Strategy Name","Put Protection") -> #REF! | M39: -0.02 | N39: =M39*L39 -> #REF! | O39: =N39/$N$45 -> #REF! | Q39: PMS | T39: QAW
Q41: QMF | R41: =VLOOKUP(Q41,$F$27:$G$29,2,FALSE) -> #N/A | T41: QAW | U41: =VLOOKUP(T41,$F$27:$G$29,2,FALSE) -> #N/A | V41: =U41/$U$47 -> #N/A
K42: Less: Interest | L42: =B4 -> 67500000 | M42: -0.09 | N42: =M42*L42 -> -6075000 | O42: =N42/$N$45 -> #REF! | Q42: PMS QFH Strategy | R42: =VLOOKUP(Q42,$F$27:$G$29,2,FALSE) -> #N/A | T42: Momentum | U42: =VLOOKUP(T42,$F$27:$G$29,2,FALSE) -> #N/A | V42: =U42/$U$47 -> #N/A
Q43: Sushila Nahar Equity MF | R43: =VLOOKUP(Q43,$F$27:$G$29,2,FALSE) -> #N/A | T43: Low Vol | U43: =VLOOKUP(T43,$F$27:$G$29,2,FALSE) -> #N/A | V43: =U43/$U$47 -> #N/A
Q44: Yogita Agrawal PMS | R44: =VLOOKUP(Q44,$F$27:$G$29,2,FALSE) -> #N/A | T44: QAW Futures | U44: =VLOOKUP(T44,$K$4:$L$22,2,FALSE) -> #N/A | V44: =U44/$U$47 -> #N/A
K45: Total | N45: =SUM(N34:N42) -> #REF! | Q45: Total | R45: =SUM(R41:R44) -> #N/A | T45: Gold Futures | U45: =VLOOKUP(T45,$K$4:$L$22,2,FALSE) -> #N/A | V45: =U45/$U$47 -> #N/A
K46: % of Networth | N46: =N45/B5 -> #REF! | T46: Gold | U46: =VLOOKUP(T46,$K$4:$L$22,2,FALSE) -> #N/A | V46: =U46/$U$47 -> #N/A
K47: % of Liquidity | N47: =N45/B3 -> #REF! | Q47: % of Networth | R47: =R45/B5 -> #N/A | T47: Total | U47: =SUM(U41:U46) -> #N/A
Q48: % of Liquidity | R48: =R45/B3 -> #N/A
T49: % of Networth | U49: =U47/B5 -> #N/A
...

Sheet Mastersheet
D2: Networth | E2: =E3-E4 -> 8.3137254e+08
D3: Liquidity | E3: ='Networth Inputs - old'!Q4 -> 8.9887254e+08 | F3: =E3/$E$2 -> 1.081191
D4: Debt | E4: ='Networth Inputs - old'!Q5 -> 67500000 | F4: =E4/$E$2 -> 0.081191038
AE7: FnO Strategies | AN7: Underlying Book | AY7: Other Ratios | BH7: Return Expectation
B8: Liquidity | L8: Investment Summary | V8: Value At Risk
AN9: Equity / Debt / Gold / Cash | AO9: Total Value | AP9: % | AY9: Risky Bets | BC9: QAW | BH9: Particulars | BI9: Exposure Values | BJ9: Expected Returns | BK9: Profits | BL9: % of total profit
B10: Rishabh Nahar | C10: =SUMIFS('Networth Inputs - old'!$E$4:$E$77,'Networth Inputs - old'!$F$4:$F$77,Mastersheet!$B$10) -> 3.8610707e+08 | D10: =C10/$E$3 -> 0.42954596 | F10: Mishayan | G10: =SUMIFS('Networth Inputs - old'!$E$4:$E$77,'Networth Inputs - old'!$F$4:$F$77,Mastersheet!$F$10) -> 5.1276547e+08 | H10: =G10/$E$3 -> 0.57045404 | N10: Total Investments | O10: =M19+Q19 -> 1.1055895e+09 | V10: Strategy | W10: % Loss | X10: Loss Value | AN10: Cash | AO10: 1.9114102e+08 | AP10: 0.1979298 | BH10: Debt | BI10: =AT36+AT37 -> 49426199 | BJ10: 0.05 | BK10: =BJ10*BI10 -> 2471310 | BL10: =BK10/$BK$17 -> 0.0069987565
N11: Leverage on Networth | O11: =O10/E2 -> 1.3298364 | V11: Long Options | W11: -1 | X11: =W11*W27 -> -24471886 | AE11: Particulars | AF11: Sum of Net Exposure | AG11: % | AI11: % of Networth | AJ11: % of Liquidity | AN11: Debt | AO11: 4.4792142e+08 | AP11: 0.46383029 | AY11: Discretionary Stock | AZ11: =VLOOKUP(AY11,$AN$22:$AO$35,2,FALSE)+VLOOKUP("Sumesh",$AN$22:$AO$35,2,FALSE) -> 47098491 | BC11: QAW | BD11: =VLOOKUP(BC11,$P$33:$R$48,2,FALSE) -> 0 | BH11: Equity | BI11: =N15 -> 5.4595181e+08 | BJ11: 0.15 | BK11: =BJ11*BI11 -> 81892771 | BL11: =BK11/$BK$17 -> 0.23192055
B12: {=IFERROR(INDEX('Networth Inputs - old'!$B$4:$B$75, MATCH(0, COUNTIF($B$12:B12, 'Networth Inputs - old'!$B$4:$B$75), 0)), "")} -> 0 | C12: =SUMIFS('Networth Inputs - old'!$E$4:$E$77,'Networth Inputs - old'!$F$4:$F$77,Mastersheet!$B$10,'Networth Inputs - old'!$B$4:$B$77,Mastersheet!B12) -> 0 | D12: =C12/$C$10 -> 0 | F12: {=IFERROR(INDEX('Networth Inputs - old'!$B$4:$B$75, MATCH(0, COUNTIF($F$12:F12, 'Networth Inputs - old'!$B$4:$B$75), 0)), "")} -> 0 | G12: =SUMIFS('Networth Inputs - old'!$E$4:$E$77,'Networth Inputs - old'!$F$4:$F$77,Mastersheet!$F$10,'Networth Inputs - old'!$B$4:$B$77,Mastersheet!F12) -> 0 | H12: =G12/$G$10 -> 0 | N12: Leverage on Liquidity | O12: =O10/E3 -> 1.2299736 | V12: PSAR | W12: -0.1 | X12: =-AA50+W12*Y45 -> -2.3954187e+08 | AE12: Gold | AF12: 304237500 | AG12: 0.042986273 | AI12: =AF12/$E$2 -> 0.36594605 | AJ12: =AF12/$E$3 -> 0.33846567 | AN12: Equity | AO12: 3.204756e+08 | AP12: 0.33185796 | AY12: % of Networth | AZ12: =AZ11/$E$2 -> 0.056651487 | BC12: Momentum | BD12: =VLOOKUP(BC12,$L$33:$N$48,2,FALSE) -> 10931181 | BH12: Gold | BI12: =N16 -> 559637687 | BJ12: 0.06 | BK12: =BJ12*BI12 -> 33578261 | BL12: =BK12/$BK$17 -> 0.095093727
B13: {=IFERROR(INDEX('Networth Inputs - old'!$B$4:$B$75, MATCH(0, COUNTIF($B$12:B13, 'Networth Inputs - old'!$B$4:$B$75), 0)), "")} -> Other Investments | C13: =SUMIFS('Networth Inputs - old'!$E$4:$E$77,'Networth Inputs - old'!$F$4:$F$77,Mastersheet!$B$10,'Networth Inputs - old'!$B$4:$B$77,Mastersheet!B13) -> 1.1484056e+08 | D13: =C13/$C$10 -> 0.2974319 | F13: {=IFERROR(INDEX('Networth Inputs - old'!$B$4:$B$75, MATCH(0, COUNTIF($F$12:F13, 'Networth Inputs - old'!$B$4:$B$75), 0)), "")} -> Other Investments | G13: =SUMIFS('Networth Inputs - old'!$E$4:$E$77,'Networth Inputs - old'!$F$4:$F$77,Mastersheet!$F$10,'Networth Inputs - old'!$B$4:$B$77,Mastersheet!F13) -> 0 | H13: =G13/$G$10 -> 0 | V13: Put Protection | W13: 0.05 | X13: =W13*M19 -> 27297590 | AE13: Gold Futures | AF13: 255400187 | AG13: 0.03608596 | AI13: =AF13/$E$2 -> 0.30720306 | AJ13: =AF13/$E$3 -> 0.28413393 | AN13: Gold | AO13: 6163056 | AP13: 0.0063819499 | AY13: % of Liquidity | AZ13: =AZ11/$E$3 -> 0.052397296 | BC13: Low Vol | BD13: =VLOOKUP(BC13,$L$33:$N$48,2,FALSE) -> 0 | BH13: Long Options | BI13: =AF15 -> 3.8923671e+09 | BJ13: 0.05 | BK13: =BJ13*BI13 -> 1.9461836e+08 | BL13: =BK13/$BK$17 -> 0.55115971
B14: {=IFERROR(INDEX('Networth Inputs - old'!$B$4:$B$75, MATCH(0, COUNTIF($B$12:B14, 'Networth Inputs - old'!$B$4:$B$75), 0)), "")} -> FD | C14: =SUMIFS('Networth Inputs - old'!$E$4:$E$77,'Networth Inputs - old'!$F$4:$F$77,Mastersheet!$B$10,'Networth Inputs - old'!$B$4:$B$77,Mastersheet!B14) -> 76648751 | D14: =C14/$C$10 -> 0.19851683 | F14: {=IFERROR(INDEX('Networth Inputs - old'!$B$4:$B$75, MATCH(0, COUNTIF($F$12:F14, 'Networth Inputs - old'!$B$4:$B$75), 0)), "")} -> FD | G14: =SUMIFS('Networth Inputs - old'!$E$4:$E$77,'Networth Inputs - old'!$F$4:$F$77,Mastersheet!$F$10,'Networth Inputs - old'!$B$4:$B$77,Mastersheet!F14) -> 5287189 | H14: =G14/$G$10 -> 0.010311125 | M14: Investment | N14: Amount | O14: % of Total Investments | P14: Leverage on Networth | Q14: Leverage on Liquidity | V14: Equities | W14: -0.2 | X14: =W14*N15 -> -1.0919036e+08 | AE14: Long Options | AF14: 1.5123121e+09 | AG14: 0.21367734 | AI14: =AF14/$E$2 -> 1.8190546 | AJ14: =AF14/$E$3 -> 1.6824544 | AN14: Grand Total | AO14: 9.657011e+08 | AP14: 1 | BC14: QAW Futures | BD14: =VLOOKUP(BC14,$L$33:$N$48,2,FALSE) -> 4.0546308e+08 | BH14: PSAR | BI14: =AF17 -> 4.0546308e+08 | BJ14: 0.1 | BK14: =BJ14*BI14 -> 40546308 | BL14: =BK14/$BK$17 -> 0.11482725
B15: {=IFERROR(INDEX('Networth Inputs - old'!$B$4:$B$75, MATCH(0, COUNTIF($B$12:B15, 'Networth Inputs - old'!$B$4:$B$75), 0)), "")} -> Prop Deposits | C15: =SUMIFS('Networth Inputs - old'!$E$4:$E$77,'Networth Inputs - old'!$F$4:$F$77,Mastersheet!$B$10,'Networth Inputs - old'!$B$4:$B$77,Mastersheet!B15) -> 1.0807881e+08 | D15: =C15/$C$10 -> 0.27991926 | F15: {=IFERROR(INDEX('Networth Inputs - old'!$B$4:$B$75, MATCH(0, COUNTIF($F$12:F15, 'Networth Inputs - old'!$B$4:$B$75), 0)), "")} -> Prop Deposits | G15: =SUMIFS('Networth Inputs - old'!$E$4:$E$77,'Networth Inputs - old'!$F$4:$F$77,Mastersheet!$F$10,'Networth Inputs - old'!$B$4:$B$77,Mastersheet!F15) -> 31500000 | H15: =G15/$G$10 -> 0.061431593 | M15: Equity | N15: =M19 -> 5.4595181e+08 | O15: =N15/$O$10 -> 0.4938106 | P15: =N15/E2 -> 0.65668732 | Q15: =N15/E3 -> 0.60737399 | V15: Gold | W15: 0.05 | X15: =W15*N16 -> 27981884 | AE15: PSAR | AF15: 3.8923671e+09 | AG15: 0.54995967 | AI15: =AF15/$E$2 -> 4.6818567 | AJ15: =AF15/$E$3 -> 4.330277 | AY15: This should not be greater than 10% | BC15: Gold Futures | BD15: =VLOOKUP(BC15,$P$33:$R$48,2,FALSE) -> 255400187
B16: {=IFERROR(INDEX('Networth Inputs - old'!$B$4:$B$75, MATCH(0, COUNTIF($B$12:B16, 'Networth Inputs - old'!$B$4:$B$75), 0)), "")} | C16: =SUMIFS('Networth Inputs - old'!$E$4:$E$77,'Networth Inputs - old'!$F$4:$F$77,Mastersheet!$B$10,'Networth Inputs - old'!$B$4:$B$77,Mastersheet!B16) -> 0 | D16: =C16/$C$10 -> 0 | F16: {=IFERROR(INDEX('Networth Inputs - old'!$B$4:$B$75, MATCH(0, COUNTIF($F$12:F16, 'Networth Inputs - old'!$B$4:$B$75), 0)), "")} | G16: =SUMIFS('Networth Inputs - old'!$E$4:$E$77,'Networth Inputs - old'!$F$4:$F$77,Mastersheet!$F$10,'Networth Inputs - old'!$B$4:$B$77,Mastersheet!F16) -> 0 | H16: =G16/$G$10 -> 0 | M16: Gold | N16: =Q34+Q35 -> 559637687 | O16: =N16/$O$10 -> 0.5061894 | P16: =N16/E2 -> 0.67314911 | Q16: =N16/E3 -> 0.6225996 | AE16: Put Protection | AF16: 6.6631014e+08 | AG16: 0.094144179 | AI16: =AF16/$E$2 -> 0.80145796 | AJ16: =AF16/$E$3 -> 0.74127322 | BC16: Gold | BD16: =VLOOKUP(BC16,$P$33:$R$48,2,FALSE) -> 304237500
B17: {=IFERROR(INDEX('Networth Inputs - old'!$B$4:$B$75, MATCH(0, COUNTIF($B$12:B17, 'Networth Inputs - old'!$B$4:$B$75), 0)), "")} -> Client Account | C17: =SUMIFS('Networth Inputs - old'!$E$4:$E$77,'Networth Inputs - old'!$F$4:$F$77,Mastersheet!$B$10,'Networth Inputs - old'!$B$4:$B$77,Mastersheet!B17) -> 86538956 | D17: =C17/$C$10 -> 0.22413201 | F17: {=IFERROR(INDEX('Networth Inputs - old'!$B$4:$B$75, MATCH(0, COUNTIF($F$12:F17, 'Networth Inputs - old'!$B$4:$B$75), 0)), "")} -> Client Account | G17: =SUMIFS('Networth Inputs - old'!$E$4:$E$77,'Networth Inputs - old'!$F$4:$F$77,Mastersheet!$F$10,'Networth Inputs - old'!$B$4:$B$77,Mastersheet!F17) -> 4.7597828e+08 | H17: =G17/$G$10 -> 0.92825728 | AE17: QAW Futures | AF17: 4.0546308e+08 | AG17: 0.05728862 | AI17: =AF17/$E$2 -> 0.48770324 | AJ17: =AF17/$E$3 -> 0.45107961 | AN17: Equity Categorisation | AS17: Debt Categorisation | BC17: Total | BD17: =SUM(BD11:BD16) -> 9.7603195e+08 | BH17: Total | BI17: =SUM(BI10:BI14) -> 5.4528459e+09 | BJ17: =BK17/BI17 -> 0.064756462 | BK17: =SUM(BK10:BK14) -> 3.5310701e+08
V18: Total Loss | X18: =SUM(X11:X16) -> -3.1792464e+08 | AE18: Stock Futures | AF18: 41460000 | AG18: 0.0058579592 | AI18: =AF18/$E$2 -> 0.04986934 | AJ18: =AF18/$E$3 -> 0.046124448 | AY18: PMS
L19: Equity / Aggressive | M19: =L24+N24 -> 5.4595181e+08 | N19: =M19/O10 -> 0.4938106 | P19: Inflation Hedge / Defensive | Q19: =P24+R24 -> 559637687 | R19: =Q19/O10 -> 0.5061894 | V19: Loss on Networth | X19: =X18/E2 -> -0.38240936 | AE19: (blank) | AG19: 0 | AI19: =AF19/$E$2 -> 0 | AJ19: =AF19/$E$3 -> 0 | AN19: Column | AO19: Value as of Today | AS19: Equity / Debt | AT19: Debt | BC19: % of Networth | BD19: =BD17/E2 -> 1.1740007
L20: Leverage on Networth | N20: =M19/E2 -> 0.65668732 | P20: Leverage on Networth | R20: =Q19/E2 -> 0.67314911 | V20: Loss on Liquidity | X20: =X18/E3 -> -0.35369268 | AE20: Gold PRCS | AF20: 0 | AG20: 0 | AI20: =AF20/$E$2 -> 0 | AJ20: =AF20/$E$3 -> 0 | AY20: QMF | AZ20: =VLOOKUP(AY20,$AN$21:$AO$35,2,FALSE) -> 47052658 | BC20: % of Liquidity | BD20: =BD17/E3 -> 1.0858402
B21: Account | C21: Rishabh Nahar | F21: Account | G21: Mishayan | L21: Leverage on Liquidity | N21: =M19/E3 -> 0.60737399 | P21: Leverage on Liquidity | R21: =Q19/E3 -> 0.6225996 | AE21: Grand Total | AF21: 7.0775501e+09 | AG21: 1 | AI21: =AF21/$E$2 -> 8.513091 | AJ21: =AF21/$E$3 -> 7.8738083 | AN21: Particulars | AO21: Total Value | AP21: % | AS21: Row Labels | AT21: Total Value | AU21: % | AY21: PMS QFH Strategy | AZ21: =VLOOKUP(AY21,$AN$21:$AO$35,2,FALSE) -> 6092676
AI22: =AF22/$E$2 -> 0 | AJ22: =AF22/$E$3 -> 0 | AN22: Large Cap | AO22: 18310601 | AP22: 0.056057667 | AS22: Affluence | AT22: 5591229.8 | AU22: 0.012482613 | AY22: Sushila Nahar Equity MF | AZ22: =VLOOKUP(AY22,$AN$21:$AO$35,2,FALSE) -> 15368350 | BC22: QAW++ to run on 2x of the book
B23: Particulars | C23: Total Value | D23: % | F23: Particulars | G23: Total Value | H23: % | L23: India | N23: Global | P23: India | R23: Global | AI23: =AF23/$E$2 -> 0 | AJ23: =AF23/$E$3 -> 0 | AN23: Momentum | AO23: 1.0285723e+08 | AP23: 0.31489607 | AS23: Aurus Alpha Deposit | AT23: 31500000 | AU23: 0.070324835 | AY23: Yogita Agrawal PMS | AZ23: =VLOOKUP(AY23,$AN$21:$AO$35,2,FALSE) -> 40685877
B24: Client Account | C24: 1.1140911e+08 | D24: 0.2629092 | F24: Client Account | G24: 5.0515882e+08 | H24: 0.9321202 | L24: =M33 -> 5.4595181e+08 | N24: =M49 -> 0 | P24: =Q33 -> 559637687 | R24: =Q49 -> 0 | AI24: =AF24/$E$2 -> 0 | AJ24: =AF24/$E$3 -> 0 | AN24: PMS QFH Strategy | AO24: 6092676 | AP24: 0.018652649 | AS24: FD | AT24: 23500000 | AU24: 0.052464559 | AY24: Total | AZ24: =SUM(AZ20:AZ23) -> 1.0919956e+08
B25: Zerodha Broking RN: Cash | C25: 14852 | D25: 3.5048547e-05 | F25: Zerodha Broking Mishayan: Cash | G25: 1.8528869e+08 | H25: 0.3418951 | L25: =L24/M19 -> 1 | N25: =N24/M19 -> 0 | P25: =P24/Q19 -> 1 | R25: =R24/Q19 -> 0 | V25: Long Options and Psar | AN25: Sushila Nahar Equity MF | AO25: 15368350 | AP25: 0.047050004 | AS25: Interest Hand | AT25: 0 | AU25: 0
B26: Zerodha Broking RN: Debt Mutual Funds | C26: 3946196.5 | D26: 0.0093124464 | F26: Zerodha Broking Mishayan: Debt Mutual Fund | G26: 1.5623862e+08 | H26: 0.28829185 | AN26: Low Vol | AO26: 29509719 | AP26: 0.09034362 | AS26: Loan to Vihaan | AT26: 3000000 | AU26: 0.0066976033 | AY26: % of Networth | AZ26: =AZ24/$E$2 -> 0.13134853 | BC26: gold | BD26: =BD16+BD15 -> 559637687
B27: Zerodha Broking RN: EQ Holdings | C27: 1.0744806e+08 | D27: 0.2535617 | F27: Zerodha Broking Mishayan: EQ Holdings | G27: 4298337.5 | H27: 0.007931302 | V27: Long Options Total Premium | W27: =SUMIFS('Strategy Allocation Old'!$G$5:$G$97,'Strategy Allocation Old'!$C$5:$C$97,"Long Options") -> 24471886 | AN27: QMF | AO27: 47052658 | AP27: 0.1440511 | AS27: Swan Capital | AT27: 5881036 | AU27: 0.013129615 | AY27: % of Liquidity | AZ27: =AZ24/$E$3 -> 0.12148503 | BC27: low vol | BD27: =BD13 -> 0
B28: Zerodha Broking RN: EQ Mutual Funds | C28: 0 | D28: 0 | F28: Zerodha Broking Mishayan: EQ Mutual Fund | G28: 1.3924535e+08 | H28: 0.25693584 | V28: % of Networth | W28: =W27/E2 -> 0.029435523 | AN28: Discretionary Stock | AO28: 27268789 | AP28: 0.083483044 | AS28: YG | AT28: 30312620 | AU28: 0.067673967 | BC28: mom | BD28: =BD12 -> 10931181
B29: FD | C29: 76648751 | D29: 0.18087984 | F29: Zerodha Broking Mishayan: Liquidbees/ Liquidcase | G29: 20087829 | H29: 0.037066108 | V29: % of Liquidity | W29: =W27/E3 -> 0.02722509 | AN29: QAW | AO29: 6163056 | AP29: 0.018868116 | AS29: Zerodha Broking Mishayan: Debt Mutual Fund | AT29: 1.5623862e+08 | AU29: 0.34880809 | AY29: This should not be more than 25%
B30: FD | C30: 23500000 | D30: 0.055456562 | F30: FD | G30: 5287189 | H30: 0.009755933 | AN30: Yogita Agrawal PMS | AO30: 40685877 | AP30: 0.12455928 | AS30: Zerodha Broking Mishayan: Liquidbees/ Liquidcase | AT30: 20087829 | AU30: 0.044846771
B31: HDFC Bank RN | C31: 1550293 | D31: 0.0036584647 | F31: HDFC Bank Mishayan | G31: 4287189 | H31: 0.0079107308 | V31: Psar Total Exposure | W31: =SUMIFS('Strategy Allocation Old'!$F$5:$F$97,'Strategy Allocation Old'!$C$5:$C$97,"PSAR") -> 3.7777797e+09 | AN31: Sumesh | AO31: 19829702 | AP31: 0.060708374 | AS31: Zerodha Broking RN: Debt Mutual Funds | AT31: 3946196.5 | AU31: 0.0088100196
B32: ICICI Bank OD | C32: 48398458 | D32: 0.11421328 | F32: HDFC Bank FD | G32: 1000000 | H32: 0.0018452022 | V32: Leverage on Networth | W32: =W31/E2 -> 4.5440274 | AE32: Strategy | AF32: Sum of Net Exposure | AN32: Sushila Nahar Zerodha | AO32: 13500000 | AP32: 0.041330075 | AS32: Affluence High Risk | AT32: 5128618.5 | AU32: 0.011449817 | AY32: Other than this we have large cap mutual funds
B33: Nimai FD | C33: 0 | D33: 0 | F33: Prop Deposits | G33: 31500000 | H33: 0.058123871 | L33: India | M33: =SUM(M34:M45) -> 5.4595181e+08 | N33: =M33/M19 -> 1 | P33: India | Q33: =SUM(Q34:Q36) -> 559637687 | R33: =Q33/Q19 -> 1 | V33: Leverage on Liquidity | W33: =W31/E3 -> 4.2027979 | AE33: Gold | AF33: 304237500 | AN33: Grand Total | AO33: 3.2663865e+08 | AP33: 1 | AS33: ICICI Bank OD | AT33: 48398458 | AU33: 0.10805122 | AY33: worth 2 cr
B34: Arvind FD | C34: 700000 | D34: 0.0016518976 | F34: Aurus Alpha Deposit | G34: 31500000 | H34: 0.058123871 | P34: Gold Futures | Q34: =SUMIFS('Strategy Allocation Old'!$F$5:$F$64,'Strategy Allocation Old'!$C$5:$C$64,Mastersheet!P34) -> 255400187 | R34: =Q34/$Q$33 -> 0.45636703 | AE34: Mishayan Zerodha Client Account | AF34: 304237500 | AS34: Jainam Allocation Deposit | AT34: 0 | AU34: 0
B35: Sumesh FD | C35: 2500000 | D35: 0.0058996342 | F35: Grand Total | G35: 5.4194601e+08 | H35: 1 | L35: QMF | M35: =SUMIFS('Mutual Funds'!$L$24:$L$79,'Mutual Funds'!$H$24:$H$79,L35)+SUMIFS('Equity Holdings'!$K$4:$K$83,'Equity Holdings'!$H$4:$H$83,L35) -> 44949446 | N35: =M35/$M$33 -> 0.08233226 | P35: Gold | Q35: =SUMIFS('Strategy Allocation Old'!$F$5:$F$64,'Strategy Allocation Old'!$C$5:$C$64,Mastersheet!P35) -> 304237500 | R35: =Q35/$Q$33 -> 0.54363297 | AE35: Gold Futures | AF35: 255400187 | AS35: Aurus Alpha Profit | AT35: 42915812 | AU35: 0.095811028
B36: Other Investments | C36: 1.1484056e+08 | D36: 0.27100692 | L36: Discretionary Stock | M36: =SUMIFS('Mutual Funds'!$L$24:$L$79,'Mutual Funds'!$H$24:$H$79,L36)+SUMIFS('Equity Holdings'!$K$4:$K$83,'Equity Holdings'!$H$4:$H$83,L36) -> 25657302 | N36: =M36/$M$33 -> 0.046995544 | P36: QAW | Q36: =SUMIFS('Mutual Funds'!$L$24:$L$79,'Mutual Funds'!$H$24:$H$79,P36)+SUMIFS('Equity Holdings'!$K$4:$K$83,'Equity Holdings'!$H$4:$H$83,P36) -> 0 | R36: =Q36/$Q$33 -> 0 | AE36: Affluence Prop | AF36: 10449600 | AS36: Marwadi Deposit | AT36: 10200000 | AU36: 0.022771851
B37: Interest Hand | C37: 0 | D37: 0 | L37: Momentum | M37: =SUMIFS('Mutual Funds'!$L$24:$L$79,'Mutual Funds'!$H$24:$H$79,L37)+SUMIFS('Equity Holdings'!$K$4:$K$83,'Equity Holdings'!$H$4:$H$83,L37) -> 10931181 | N37: =M37/$M$33 -> 0.020022246 | V37: PSAR Portfolio Values | AE37: Aurus Alpha | AF37: 116732187 | AN37: Cash Categorisation | AS37: Marwadi Profits | AT37: 39226199 | AU37: 0.08757384
B38: Loan to Vihaan | C38: 3000000 | D38: 0.0070795611 | L38: Low Vol | M38: =SUMIFS('Mutual Funds'!$L$24:$L$79,'Mutual Funds'!$H$24:$H$79,L38)+SUMIFS('Equity Holdings'!$K$4:$K$83,'Equity Holdings'!$H$4:$H$83,L38) -> 0 | N38: =M38/$M$33 -> 0 | AE38: SRE | AF38: 0 | AS38: Marwadi FPI Deposit (FD) | AT38: 2625000 | AU38: 0.0058604029
B39: PMS QFH Strategy | C39: 6092676 | D39: 0.014377824 | L39: Large Cap | M39: =SUMIFS('Mutual Funds'!$L$24:$L$79,'Mutual Funds'!$H$24:$H$79,L39)+SUMIFS('Equity Holdings'!$K$4:$K$83,'Equity Holdings'!$H$4:$H$83,L39) -> 0 | N39: =M39/$M$33 -> 0 | V39: Strategy Name | W39: PSAR | AE39: Marwadi | AF39: 90922400 | AN39: Equity / Debt | AO39: Cash | AS39: HDFC Bank FD | AT39: 1000000 | AU39: 0.0022325344
B40: Sushila Nahar Equity MF | C40: 15368350 | D40: 0.036267057 | L40: Sushila Nahar Equity MF | M40: =SUMIFS('Mutual Funds'!$L$24:$L$79,'Mutual Funds'!$H$24:$H$79,L40)+SUMIFS('Equity Holdings'!$K$4:$K$83,'Equity Holdings'!$H$4:$H$83,L40) -> 0 | N40: =M40/$M$33 -> 0 | AE40: Marwadi FPI | AF40: 37296000 | AS40: Marwadi FPI Profits | AT40: 15169806 | AU40: 0.033867114
B41: Swan Capital | C41: 5881036 | D41: 0.013878384 | L41: Yogita Agrawal PMS | M41: =SUMIFS('Mutual Funds'!$L$24:$L$79,'Mutual Funds'!$H$24:$H$79,L41)+SUMIFS('Equity Holdings'!$K$4:$K$83,'Equity Holdings'!$H$4:$H$83,L41) -> 0 | N41: =M41/$M$33 -> 0 | V41: Account | W41: Portfolio Value | X41: Psar Multiplier | Y41: Total Exposure | Z41: Hedge | AA41: VAR | AE41: Long Options | AF41: 1.5123121e+09 | AN41: Particulars | AO41: Total Value | AP41: % | AS41: Nimai FD | AT41: 0 | AU41: 0
B42: YG | C42: 30312620 | D42: 0.071533348 | L42: PMS QFH Strategy | M42: =SUMIFS('Mutual Funds'!$L$24:$L$79,'Mutual Funds'!$H$24:$H$79,L42)+SUMIFS('Equity Holdings'!$K$4:$K$83,'Equity Holdings'!$H$4:$H$83,L42) -> 0 | N42: =M42/$M$33 -> 0 | V42: Affluence High Risk | W42: 20737500 | X42: 6 | Y42: 124425000 | Z42: 0.1 | AA42: =IF(Z42>0%,W42*Z42,Z42*Y42) -> 2073750 | AE42: Affluence High Risk | AF42: 20737500 | AN42: HDFC Bank Mishayan | AO42: 4287189 | AP42: 0.022429455 | AS42: Arvind FD | AT42: 700000 | AU42: 0.0015627741
B43: Yogita Agrawal PMS | C43: 40685877 | D43: 0.096012717 | L43: Stock Futures | M43: =SUMIFS('Strategy Allocation Old'!$F$5:$F$64,'Strategy Allocation Old'!$C$5:$C$64,Mastersheet!L43) -> 41460000 | N43: =M43/$M$33 -> 0.075940769 | V43: Affluence Prop | W43: 26124000 | X43: 3 | Y43: 78372000 | Z43: 0.1 | AA43: =IF(Z43>0%,W43*Z43,Z43*Y43) -> 2612400 | AE43: Affluence Prop | AF43: 26124000 | AN43: HDFC Bank RN | AO43: 1550293 | AP43: 0.0081107289 | AS43: Sumesh FD | AT43: 2500000 | AU43: 0.0055813361
...

Sheet Capital Account
A2: Mishayan Capital Account Number as per Accounts | I2: Note: | V2: Current Liquidity | Z2: Mishayan Actual Liquidity | AD2: Rishabh Actual Liquidity | AI2: Networth
I3: FnO Open Positions End of Year WILL BE SUBTRACTED FROM REVENUE HENCE NEGATIVE
A4: Year | B4: FY | C4: Revenue / Expense | D4: Category | E4: Amount | I4: FnO Open Positions Start of Year WILL BE ADDED FROM REVENUE HENCE POSITIVE | V4: Particulars | W4: Sum of Value | Z4: Particulars | AA4: Value | AD4: Particulars | AE4: Value | AF4: BS | AJ4: Mishayan | AK4: Rishabh | AL4: Total
A5: 1 | B5: 2023-24 | C5: Revenue | D5: Consultancy Fees | E5: 1700000 | V5: Mishayan | W5: 5.4194601e+08 | Z5: Total | AA5: =SUM(AA6:AA38) -> 3.5902084e+08 | AD5: Total | AE5: =SUM(AE6:AE38) -> 6.0668026e+08 | AI5: Liquidity | AJ5: =AA5 -> 3.5902084e+08 | AK5: =AE5 -> 6.0668026e+08 | AL5: =AJ5+AK5 -> 9.657011e+08
A6: 2 | B6: 2024-25 | C6: Revenue | D6: Equity and Non Equity Profits | E6: 31 | V6: Aurus Alpha Deposit | W6: 31500000 | Z6: =V6 -> Aurus Alpha Deposit | AA6: =W6 -> 31500000 | AD6: =V15 -> Affluence | AE6: =W15 -> 5591229.8 | AF6: Off | AI6: Less: Debt | AJ6: 35300000 | AK6: ='Networth Inputs - old'!M4+'Networth Inputs - old'!M5+'Networth Inputs - old'!M6-'Capital Account'!AJ6+'Networth Inputs - old'!M7 -> 32200000 | AL6: =AJ6+AK6 -> 67500000
A7: 2 | B7: 2024-25 | C7: Expense | D7: Equity and Non Equity Other Debits | E7: -9594.1988 | J7: Row Labels | K7: Sum of Amount | V7: HDFC Bank Mishayan | W7: 4287189 | Z7: =V7 -> HDFC Bank Mishayan | AA7: =W7 -> 4287189 | AD7: =V16 -> Affluence High Risk | AE7: =W16 -> 5128618.5 | AF7: Off | AI7: Networth | AJ7: =AJ5-AJ6 -> 3.2372084e+08 | AK7: =AK5-AK6 -> 5.7448026e+08 | AL7: =AJ7+AK7 -> 8.982011e+08
A8: 2 | B8: 2024-25 | C8: Revenue | D8: Mutual Fund Profits | E8: -48533.882 | J8: 2023-24 | K8: 1192790 | V8: Zerodha Broking Mishayan: Cash | W8: 1.8528869e+08 | Z8: =V8 -> Zerodha Broking Mishayan: Cash | AA8: =W8 -> 1.8528869e+08 | AD8: =V17 -> FD | AE8: =W17 -> 23500000 | AF8: Off
A9: 2 | B9: 2024-25 | C9: Revenue | D9: FnO Profits | E9: 17841191 | J9: Expense | K9: -63743 | V9: Zerodha Broking Mishayan: Debt Mutual Fund | W9: 1.5623862e+08 | Z9: =V9 -> Zerodha Broking Mishayan: Debt Mutual Fund | AA9: =W9 -> 1.5623862e+08 | AD9: =V18 -> HDFC Bank RN | AE9: =W18 -> 1550293
A10: 2 | B10: 2024-25 | C10: Expense | D10: Fno Charges | E10: -1252925.9 | J10: Audit/Professional Fees | K10: -63743 | V10: Zerodha Broking Mishayan: EQ Holdings | W10: 4298337.5 | Z10: =V10 -> Zerodha Broking Mishayan: EQ Holdings | AA10: =W10 -> 4298337.5 | AD10: =V19 -> ICICI Bank OD | AE10: =W19 -> 48398458
A11: 2 | B11: 2024-25 | C11: Revenue | D11: FnO Open Positions End of Year | E11: -15847722 | J11: Revenue | K11: 1700000 | V11: Zerodha Broking Mishayan: EQ Mutual Fund | W11: 1.3924535e+08 | Z11: =V11 -> Zerodha Broking Mishayan: EQ Mutual Fund | AA11: =W11 -> 1.3924535e+08 | AD11: =V20 -> Interest Hand | AE11: =W20 -> 0 | AF11: Off | AI11: Liquidity
A12: 2 | B12: 2024-25 | C12: Revenue | D12: FnO Open Positions Start of Year | E12: =0 -> 0 | J12: Consultancy Fees | K12: 1700000 | V12: Zerodha Broking Mishayan: Liquidbees/ Liquidcase | W12: 20087829 | Z12: =V12 -> Zerodha Broking Mishayan: Liquidbees/ Liquidcase | AA12: =W12 -> 20087829 | AD12: =V21 -> Loan to Vihaan | AE12: =W21 -> 3000000 | AF12: On
A13: 2 | B13: 2024-25 | C13: Revenue | D13: Equity Dividends | E13: 0 | J13: Taxes | K13: -443467 | V13: HDFC Bank FD | W13: 1000000 | Z13: =V13 -> HDFC Bank FD | AA13: =W13 -> 1000000 | AD13: =V22 -> PMS QFH Strategy | AE13: =W22 -> 6092676 | AF13: On | AJ13: Mishayan | AK13: Rishabh | AL13: Total
A14: 3 | B14: 2025-26 | C14: Expense | D14: Equity and Non Equity Other Debits | E14: -13550.635 | J14: Taxes | K14: -443467 | V14: Rishabh Nahar | W14: 4.2375508e+08 | AD14: =V23 -> Sushila Nahar Equity MF | AE14: =W23 -> 15368350 | AI14: On | AJ14: =AJ5 -> 3.5902084e+08 | AK14: =SUMIFS($AE$7:$AE$110,$AF$7:$AF$110,AI14) -> 4.6870231e+08 | AL14: =AJ14+AK14 -> 8.2772315e+08
A15: 3 | B15: 2025-26 | C15: Revenue | D15: FnO Profits | E15: 93867317 | J15: 2024-25 | K15: 8905814.4 | V15: Affluence | W15: 5591229.8 | AD15: =V24 -> Swan Capital | AE15: =W24 -> 5881036 | AF15: On | AI15: Off | AK15: =SUMIFS($AE$7:$AE$110,$AF$7:$AF$110,AI15) -> 67069621 | AL15: =AJ15+AK15 -> 67069621
A16: 3 | B16: 2025-26 | C16: Expense | D16: Fno Charges | E16: -4109562.8 | J16: Expense | K16: -2175687.1 | V16: Affluence High Risk | W16: 5128618.5 | AD16: =V25 -> YG | AE16: =W25 -> 30312620 | AF16: On
A17: 3 | B17: 2025-26 | C17: Revenue | D17: MCX Profits | E17: 60547800 | J17: Audit/Professional Fees | K17: -144780 | V17: FD | W17: 23500000 | Z17: Adjusting EQ Holdings | AA17: 0 | AD17: =V26 -> Yogita Agrawal PMS | AE17: =W26 -> 40685877 | AF17: On
A18: 3 | B18: 2025-26 | C18: Expense | D18: MCX Charges | E18: -195217.63 | J18: Equity and Non Equity Other Debits | K18: -9594.1988 | V18: HDFC Bank RN | W18: 1550293 | Z18: Adjusting MF Holdings | AA18: =-('Holdings Summary'!T19-'Holdings Summary'!AB9) -> -1.8292518e+08 | AD18: =V27 -> Zerodha Broking RN: Cash | AE18: =W27 -> 14852 | AF18: On
A19: 3 | B19: 2025-26 | C19: Revenue | D19: FnO Open Positions End of Year | E19: 0 | G19: -40702648 | J19: Fno Charges | K19: -1252925.9 | V19: ICICI Bank OD | W19: 48398458 | AD19: =V28 -> Zerodha Broking RN: Debt Mutual Funds | AE19: =W28 -> 3946196.5 | AF19: Off
A20: 3 | B20: 2025-26 | C20: Revenue | D20: FnO Open Positions Start of Year | E20: 15847722 | J20: Salary | K20: -706750 | V20: Interest Hand | W20: 0 | AD20: =V29 -> Zerodha Broking RN: EQ Holdings | AE20: =W29 -> 1.0744806e+08 | AF20: On
A21: 2 | B21: 2024-25 | C21: Revenue | D21: Consultancy Fees | E21: 12257627 | J21: Others | K21: -61637 | V21: Loan to Vihaan | W21: 3000000 | AD21: =V30 -> Zerodha Broking RN: EQ Mutual Funds | AE21: =W30 -> 0 | AF21: On
A22: 2 | B22: 2024-25 | C22: Revenue | D22: Other | E22: 5221.78 | J22: Revenue | K22: 14207815 | V22: PMS QFH Strategy | W22: 6092676 | AD22: =V31 -> Aurus Alpha Profit | AE22: =W31 -> 42915812 | AF22: On
A23: 1 | B23: 2023-24 | C23: Expense | D23: Audit/Professional Fees | E23: -63743 | J23: Consultancy Fees | K23: 12257627 | V23: Sushila Nahar Equity MF | W23: 15368350 | AD23: =V32 -> Marwadi Deposit | AE23: =W32 -> 10200000 | AF23: On
A24: 2 | B24: 2024-25 | C24: Expense | D24: Audit/Professional Fees | E24: -144780 | J24: Equity and Non Equity Profits | K24: 31 | V24: Swan Capital | W24: 5881036 | AD24: =V33 -> Marwadi Profits | AE24: =W33 -> 39226199 | AF24: On
A25: 3 | B25: 2025-26 | C25: Expense | D25: Audit/Professional Fees | E25: -5782 | J25: Equity Dividends | K25: 0 | V25: YG | W25: 30312620 | AD25: =V34 -> Marwadi FPI Deposit (FD) | AE25: =W34 -> 2625000 | AF25: Off
A26: 1 | B26: 2023-24 | C26: Taxes | D26: Taxes | E26: -443467 | J26: FnO Open Positions End of Year | K26: -15847722 | V26: Yogita Agrawal PMS | W26: 40685877 | AD26: =V35 -> Marwadi FPI Profits | AE26: =W35 -> 15169806 | AF26: Off
A27: 2 | B27: 2024-25 | C27: Taxes | D27: Taxes | E27: -3126313 | J27: FnO Open Positions Start of Year | K27: 0 | V27: Zerodha Broking RN: Cash | W27: 14852 | AD27: =V36 -> Nimai FD | AE27: =W36 -> 0 | AF27: Off
A28: 3 | B28: 2025-26 | C28: Taxes | D28: Taxes | E28: 0 | J28: FnO Profits | K28: 17841191 | V28: Zerodha Broking RN: Debt Mutual Funds | W28: 3946196.5 | AD28: =V37 -> Arvind FD | AE28: =W37 -> 700000 | AF28: Off
A29: 2 | B29: 2024-25 | C29: Expense | D29: Salary | E29: -706750 | J29: Mutual Fund Profits | K29: -48533.882 | Q29: unrealised pnl | V29: Zerodha Broking RN: EQ Holdings | W29: 1.0744806e+08 | AD29: =V38 -> Sushila Nahar HDFC | AE29: =W38 -> 0 | AF29: Off
A30: 2 | B30: 2024-25 | C30: Expense | D30: Others | E30: -61637 | J30: Other | K30: 5221.78 | O30: Current Open Holdings value which were purchased in Mishayan | P30: =SUM(P31:P35) -> 91154088 | Q30: =SUM(Q31:Q35) -> 2550599.2 | V30: Zerodha Broking RN: EQ Mutual Funds | W30: 0 | AD30: =V39 -> Sushila Nahar Zerodha | AE30: =W39 -> 13500000 | AF30: Off
A31: 3 | B31: 2025-26 | C31: Expense | D31: Salary | E31: -633500 | J31: Taxes | K31: -3126313 | O31: ADITYA BIRLA SUN LIFE MONEY MANAGER FUND - DIRECT PLAN | P31: 30987326 | Q31: 988714 | V31: Aurus Alpha Profit | W31: 42915812 | AD31: =V40 -> Sumesh FD | AE31: =W40 -> 2500000 | AF31: Off
A32: 3 | B32: 2025-26 | C32: Expense | D32: Others | E32: -324443.52 | J32: Taxes | K32: -3126313 | O32: EDELWEISS NIFTY MIDCAP 150 MOMENTUM 50 INDEX FUND - DIRECT PLAN | P32: 7440385 | Q32: 692480 | V32: Marwadi Deposit | W32: 10200000
A33: 3 | B33: 2025-26 | C33: Revenue | D33: Consultancy Fees | E33: 10000000 | J33: 2025-26 | K33: 2.0014338e+08 | O33: HDFC NIFTY200 Momentum 30 Index Fund | P33: 4166308 | Q33: 418119 | V33: Marwadi Profits | W33: 39226199
A34: 3 | B34: 2025-26 | C34: Revenue | D34: Mcx Open Positions End of Year | E34: =--2032400.2 -> 2032400.2 | J34: Expense | K34: -5282056.6 | O34: LIC MF LIQUID FUND - DIRECT PLAN | P34: 40322052 | Q34: 324057 | V34: Marwadi FPI Deposit (FD) | W34: 2625000
A35: 3 | B35: 2025-26 | C35: Revenue | D35: Mcx Open Positions Start of Year | E35: 0 | J35: Audit/Professional Fees | K35: -5782 | O35: LIQUIDCASE | P35: =8110787.6+127229.2 -> 8238016.8 | Q35: =127229.2 -> 127229.2 | V35: Marwadi FPI Profits | W35: 15169806
A36: 3 | B36: 2025-26 | C36: Revenue | D36: Mcx Unrealised Fut pnl at End of Year | E36: 23130200 | J36: Equity and Non Equity Other Debits | K36: -13550.635 | V36: Nimai FD | W36: 0
J37: Fno Charges | K37: -4109562.8 | V37: Arvind FD | W37: 700000 | AD37: Adjusting EQ Holdings
J38: MCX Charges | K38: -195217.63 | O38: Unrealised Pnl | P38: =SUM(P39:P40) -> 26747539 | V38: Sushila Nahar HDFC | W38: 0 | AD38: Adjusting MF Holdings | AE38: ='Holdings Summary'!T19-'Holdings Summary'!AB9 -> 1.8292518e+08 | AF38: On
J39: Salary | K39: -633500 | O39: Fno | P39: 1584939 | V39: Sushila Nahar Zerodha | W39: 13500000
J40: Others | K40: -324443.52 | O40: Mcx | P40: =E34+E36 -> 25162600 | V40: Sumesh FD | W40: 2500000
J41: Revenue | K41: 2.0542544e+08 | V41: (blank)
...

Sheet Holdings Summary
A1: Current Stock Holdings in Mishayan | E1: Current Stock Holdings in RN | I1: Holdings Initially Bought in Mishayan | L1: Holdings Initially Bought in RN | S1: Current Mutual Fund Holdings in Mishayan | W1: Current Mutual Fund Holdings in RN | AA1: Mutual Funds Initially Bought in Mishayan | AE1: Mutual Funds Initially Bought in RN
A3: Mastersheet Tag | B3: Stock Holdings | E3: Mastersheet Tag | F3: Personal Stock Holdings Zerodha | I3: Notes | J3: Bought in Mishayan | L3: Notes | M3: Bought in RN | S3: Mastersheet Tag | T3: Mutual Funds | W3: Mastersheet Tag | X3: Personal Mutual Funds Zerodha | AA3: Notes | AB3: Bought in Mishayan | AE3: Notes | AF3: (Multiple Items)
A5: Holdings | B5: Value | E5: Holdings | F5: Value | I5: Holdings | J5: Value | L5: Holdings | M5: Value | S5: Holdings | T5: Value | W5: Holdings | X5: Value | AA5: Holdings | AB5: Value | AE5: Holdings | AF5: Value
A6: Bought in Mishayan | B6: 24386167 | E6: Bought in RN | F6: 1.0744806e+08 | I6: Debt | J6: 20087829 | L6: Equity | M6: 1.0128501e+08 | S6: Bought in Mishayan | T6: 92406491 | W6: Bought in RN | X6: 3946196.5 | AA6: Debt | AB6: 92406491 | AE6: Debt | AF6: 47626022
A7: Debt | B7: 20087829 | E7: Equity | F7: 1.0128501e+08 | I7: LIQUIDCASE | J7: 20087829 | L7: ALLETEC-SM | M7: 1027440 | S7: ADITYA BIRLA SUN LIFE MONEY MANAGER FUND - DIRECT PLAN | T7: 51528623 | W7: LIC MF LIQUID FUND - DIRECT PLAN | X7: 3946196.5 | AA7: ADITYA BIRLA SUN LIFE MONEY MANAGER FUND - DIRECT PLAN | AB7: 51528623 | AE7: ADITYA BIRLA SUN LIFE LIQUID FUND - DIRECT PLAN | AF7: 5666626.8
A8: LIQUIDCASE | B8: 20087829 | E8: ALLETEC-SM | F8: 1027440 | I8: Equity | J8: 4298337.5 | L8: ALPEXSOLAR-SM | M8: 10842900 | S8: LIC MF LIQUID FUND - DIRECT PLAN | T8: 40877868 | W8: Grand Total | X8: 3946196.5 | AA8: LIC MF LIQUID FUND - DIRECT PLAN | AB8: 40877868 | AE8: LIC MF LIQUID FUND - DIRECT PLAN | AF8: 3946196.5
A9: Equity | B9: 4298337.5 | E9: ALPEXSOLAR-SM | F9: 10842900 | I9: EXHICON | J9: 4298337.5 | L9: BALUFORGE | M9: 1359213.8 | S9: Bought in RN and Loaned to Mishayan | T9: 1.8292518e+08 | AA9: Grand Total | AB9: 92406491 | AE9: TATA LIQUID FUND - DIRECT PLAN | AF9: 38013199
A10: EXHICON | B10: 4298337.5 | E10: BALUFORGE | F10: 1359213.8 | I10: Grand Total | J10: 24386167 | L10: BBOX | M10: 2052562.2 | S10: ADITYA BIRLA SUN LIFE LIQUID FUND - DIRECT PLAN | T10: 5666626.8 | AE10: Equity | AF10: 1.3924535e+08
A11: Grand Total | B11: 24386167 | E11: BBOX | F11: 2052562.2 | L11: CAPLIPOINT | M11: 1511517.6 | S11: AXIS NIFTY500 MOMENTUM 50 INDEX FUND - DIRECT PLAN | T11: 3658679.9 | AE11: AXIS NIFTY500 MOMENTUM 50 INDEX FUND - DIRECT PLAN | AF11: 3658679.9
E12: CAPLIPOINT | F12: 1511517.6 | L12: CUB | M12: 2279628.5 | S12: ICICI PRUDENTIAL NIFTY 100 LOW VOLATILITY 30 ETF FOF - DIRECT PLAN | T12: 29509719 | AE12: ICICI PRUDENTIAL NIFTY 100 LOW VOLATILITY 30 ETF FOF - DIRECT PLAN | AF12: 29509719
E13: CUB | F13: 2279628.5 | L13: DEEPAKFERT | M13: 1263716.2 | S13: KOTAK NIFTY 200 MOMENTUM 30 INDEX FUND - DIRECT PLAN | T13: 39996120 | AE13: KOTAK NIFTY 200 MOMENTUM 30 INDEX FUND - DIRECT PLAN | AF13: 39996120
E14: DEEPAKFERT | F14: 1263716.2 | L14: DYCL | M14: 1284227.6 | S14: MOTILAL OSWAL NIFTY 500 MOMENTUM 50 INDEX FUND - DIRECT PLAN | T14: 8390499.8 | AE14: MOTILAL OSWAL NIFTY 500 MOMENTUM 50 INDEX FUND - DIRECT PLAN | AF14: 8390499.8
E15: DYCL | F15: 1284227.6 | L15: HOMEFIRST | M15: 1513289.2 | S15: PARAG PARIKH ELSS TAX SAVER FUND - DIRECT PLAN | T15: 243120.85 | AE15: PARAG PARIKH ELSS TAX SAVER FUND - DIRECT PLAN | AF15: 243120.85
E16: HOMEFIRST | F16: 1513289.2 | L16: ICRA | M16: 1649046 | S16: QUANT LARGE CAP FUND - DIRECT PLAN | T16: 18067480 | AE16: QUANT LARGE CAP FUND - DIRECT PLAN | AF16: 18067480
E17: ICRA | F17: 1649046 | L17: IIFLCAPS | M17: 4912865.4 | S17: TATA LIQUID FUND - DIRECT PLAN | T17: 38013199 | AE17: TATA NIFTY MIDCAP 150 MOMENTUM 50 INDEX FUND - DIRECT PLAN | AF17: 39379733
E18: IIFLCAPS | F18: 4912865.4 | L18: INDIASHLTR | M18: 1595409.2 | S18: TATA NIFTY MIDCAP 150 MOMENTUM 50 INDEX FUND - DIRECT PLAN | T18: 39379733 | AE18: Grand Total | AF18: 1.8687137e+08
E19: INDIASHLTR | F19: 1595409.2 | L19: KARURVYSYA | M19: 2446471.8 | S19: Grand Total | T19: 2.7533167e+08
E20: KARURVYSYA | F20: 2446471.8 | L20: KPL | M20: 3194246.4
E21: KPL | F21: 3194246.4 | L21: KRBL | M21: 1290143.8
E22: KRBL | F22: 1290143.8 | L22: KRISHANA | M22: 1705914.6
E23: KRISHANA | F23: 1705914.6 | L23: MPSLTD | M23: 1342478.9
E24: MPSLTD | F24: 1342478.9 | L24: PENIND | M24: 1115123.8
E25: PENIND | F25: 1115123.8 | L25: POKARNA | M25: 1899432.4
E26: POKARNA | F26: 1899432.4 | L26: POWERMECH | M26: 1312887.2
E27: POWERMECH | F27: 1312887.2 | L27: REGENCY | M27: 11513024
E28: REGENCY | F28: 11513024 | L28: SBFC | M28: 1570171.7
E29: SBFC | F29: 1570171.7 | L29: SHAKTIPUMP | M29: 1164644.2 | W29: =T26+X19 -> 0
E30: SHAKTIPUMP | F30: 1164644.2 | L30: SHREEPUSHK | M30: 1635722.4
E31: SHREEPUSHK | F31: 1635722.4 | L31: SKIPPER | M31: 1298922.5
E32: SKIPPER | F32: 1298922.5 | L32: SRM | M32: 1541877.6
E33: SRM | F33: 1541877.6 | L33: STEELCAS | M33: 2077107.7
E34: STEELCAS | F34: 2077107.7 | L34: SUPRIYA | M34: 1695047.7
E35: SUPRIYA | F35: 1695047.7 | L35: SYNCOMF | M35: 1359858.9
E36: SYNCOMF | F36: 1359858.9 | L36: TCPLPACK | M36: 1383361
E37: TCPLPACK | F37: 1383361 | L37: WELCORP | M37: 1813395
E38: WELCORP | F38: 1813395 | L38: ZTECH-SM | M38: 1669800
E39: ZTECH-SM | F39: 1669800 | L39: MONIKA | M39: 4281200
E40: MONIKA | F40: 4281200 | L40: FISCHER | M40: 1815500
E41: FISCHER | F41: 1815500 | L41: CCAVENUE | M41: 3510000
... E48: GOLDBEES | F48: 6163056 | L48: Grand Total | M48: 1.0744806e+08
...

Sheet Networth Inputs
A1: Liquidity | M1: Debt: | T1: Networth:
A3: Sr. No. | B3: Category | C3: Particulars 1 | D3: Particulars 2 | E3: Equity / Debt / Cash | F3: Value | G3: Mishayan / Rishabh | H3: On / Off | I3: Data as of | J3: Attachment Available | M3: Sr. No. | N3: Category | O3: Particulars | P3: Value | Q3: Mishayan / Rishabh | T3: Particulars | U3: Value
A4: 1 | B4: Client Account | C4: Zerodha Broking RN | D4: Equity Holdings | E4: Equity | F4: =SUMIFS('Equity Holdings'!$K$4:$K$82,'Equity Holdings'!$G$4:$G$82,'Networth Inputs'!E4,'Equity Holdings'!$B$4:$B$82,"Personal Stock Holdings Zerodha") -> 96365514 | G4: Rishabh | H4: On | I4: 46112 | J4: Yes | M4: 1 | N4: Debt | O4: ICICI Bank OD | P4: 65000000 | Q4: Rishabh | T4: Liquidity | U4: =SUM(F4:F123) -> 9.1849659e+08
A5: =A4+1 -> 2 | B5: Client Account | C5: Zerodha Broking RN | D5: Debt Holdings | E5: Debt | F5: =SUMIFS('Equity Holdings'!$K$4:$K$82,'Equity Holdings'!$G$4:$G$82,'Networth Inputs'!E5,'Equity Holdings'!$B$4:$B$82,"Personal Stock Holdings Zerodha") -> 0 | G5: Rishabh | H5: On | I5: 46112 | J5: Yes | M5: 2 | N5: Debt | O5: Sumesh | P5: 2500000 | Q5: Rishabh | T5: Less: Debt | U5: =SUM(P4:P123) -> 67500000
A6: =A5+1 -> 3 | B6: Client Account | C6: Zerodha Broking RN | D6: Gold Holdings | E6: Gold | F6: =SUMIFS('Equity Holdings'!$K$4:$K$82,'Equity Holdings'!$G$4:$G$82,'Networth Inputs'!E6,'Equity Holdings'!$B$4:$B$82,"Personal Stock Holdings Zerodha") -> 6156452 | G6: Rishabh | H6: On | I6: 46112 | J6: Yes | T6: Networth | U6: =U4-U5 -> 8.5099659e+08
A7: =A6+1 -> 4 | B7: Client Account | C7: Zerodha Broking RN | D7: Equity Mutual Fund Holdings | E7: Equity | F7: =SUMIFS('Mutual Funds'!$L$4:$L$92,'Mutual Funds'!$G$4:$G$92,'Networth Inputs'!E7,'Mutual Funds'!$H$4:$H$92,"Personal Mutual Funds Zerodha") -> 1.3401375e+08 | G7: Rishabh | H7: On | I7: 46112 | J7: Yes
A8: =A7+1 -> 5 | B8: Client Account | C8: Zerodha Broking RN | D8: Debt Mutual Fund Holdings | E8: Debt | F8: =SUMIFS('Mutual Funds'!$L$4:$L$92,'Mutual Funds'!$G$4:$G$92,'Networth Inputs'!E8,'Mutual Funds'!$H$4:$H$92,"Personal Mutual Funds Zerodha") -> 0 | G8: Rishabh | H8: On | I8: 46112 | J8: Yes
A9: =A8+1 -> 6 | B9: Client Account | C9: Zerodha Broking RN | D9: Cash | E9: Cash | F9: 1014842.1 | G9: Rishabh | H9: On | I9: 46112 | J9: No
A10: =A9+1 -> 7 | B10: Client Account | C10: Zerodha Broking RN | D10: Contract Value | E10: Cash | F10: 0 | G10: Rishabh | H10: On | I10: 46112 | J10: No
A12: =A10+1 -> 8 | B12: Client Account | C12: Zerodha Broking Mishayan | D12: Equity Holdings | E12: Equity | F12: =SUMIFS('Equity Holdings'!$K$4:$K$82,'Equity Holdings'!$G$4:$G$82,'Networth Inputs'!E12,'Equity Holdings'!$B$4:$B$82,"Stock Holdings") -> 2663212 | G12: Mishayan | H12: On | I12: 46112 | J12: Yes
A13: =A12+1 -> 9 | B13: Client Account | C13: Zerodha Broking Mishayan | D13: Debt Holdings | E13: Debt | F13: =SUMIFS('Equity Holdings'!$K$4:$K$82,'Equity Holdings'!$G$4:$G$82,'Networth Inputs'!E13,'Equity Holdings'!$B$4:$B$82,"Stock Holdings") -> 0 | G13: Mishayan | H13: On | I13: 46112 | J13: Yes
A14: =A13+1 -> 10 | B14: Client Account | C14: Zerodha Broking Mishayan | D14: Gold Holdings | E14: Gold | F14: =SUMIFS('Equity Holdings'!$K$4:$K$82,'Equity Holdings'!$G$4:$G$82,'Networth Inputs'!E14,'Equity Holdings'!$B$4:$B$82,"Stock Holdings") -> 0 | G14: Mishayan | H14: On | I14: 46112 | J14: Yes
A15: =A14+1 -> 11 | B15: Client Account | C15: Zerodha Broking Mishayan | D15: Equity Mutual Fund Holdings | E15: Equity | F15: =SUMIFS('Mutual Funds'!$L$4:$L$92,'Mutual Funds'!$G$4:$G$92,'Networth Inputs'!E15,'Mutual Funds'!$H$4:$H$92,"Mutual Funds") -> 0 | G15: Mishayan | H15: On | I15: 46112 | J15: Yes
A16: =A15+1 -> 12 | B16: Client Account | C16: Zerodha Broking Mishayan | D16: Debt Mutual Fund Holdings | E16: Debt | F16: =SUMIFS('Mutual Funds'!$L$4:$L$92,'Mutual Funds'!$G$4:$G$92,'Networth Inputs'!E16,'Mutual Funds'!$H$4:$H$92,"Mutual Funds") -> 1.1272582e+08 | G16: Mishayan | H16: On | I16: 46112 | J16: Yes
A17: =A16+1 -> 13 | B17: Client Account | C17: Zerodha Broking Mishayan | D17: Cash | E17: Cash | F17: =75890878.49 -> 75890878 | G17: Mishayan | H17: On | I17: 46112 | J17: No
A18: =A17+1 -> 14 | B18: Client Account | C18: Zerodha Broking Mishayan | D18: Contract Value | E18: Cash | F18: 201357611 | G18: Mishayan | H18: On | I18: 46112 | J18: No
A20: =A18+1 -> 15 | B20: Prop | C20: Jainam | D20: Jainam - Deposit | E20: Debt | F20: 31500000 | G20: Mishayan | H20: On | I20: 46112 | J20: No
A21: =A20+1 -> 16 | B21: Prop | C21: Jainam | D21: Jainam - Profit and Loss | E21: Debt | F21: 35000000 | G21: Rishabh | H21: Off | I21: 46112 | J21: No
A22: =A21+1 -> 17 | B22: Prop | C22: Jainam | D22: Jainam - Allocation Deposit | E22: Debt | F22: 0 | G22: Rishabh | H22: Off | I22: 46112 | J22: No
A23: =A22+1 -> 18 | B23: Prop | C23: Marwadi Prop | D23: Marwadi Prop - Deposit | E23: Debt | F23: 10200000 | G23: Rishabh | H23: Off | I23: 46112 | J23: No
A24: =A23+1 -> 19 | B24: Prop | C24: Marwadi Prop | D24: Marwadi Prop - Profit and Loss | E24: Debt | F24: =34978573.9+251926.56 -> 35230500 | G24: Rishabh | H24: Off | I24: 46112 | J24: No
A25: =A24+1 -> 20 | B25: Prop | C25: Marwadi FPI | D25: Marwadi FPI - Deposit | E25: Debt | F25: 2625000 | G25: Rishabh | H25: Off | I25: 46112 | J25: No
A26: =A25+1 -> 21 | B26: Prop | C26: Marwadi FPI | D26: Marwadi FPI - Profit and Loss | E26: Debt | F26: =13482336.48+6.3%*(-68598797) -> 9160612.3 | G26: Rishabh | H26: On | I26: 46112 | J26: No
A27: =A26+1 -> 22 | B27: Prop | C27: Affluence Prop | D27: Affluence Prop - Deposit | E27: Debt | F27: 0 | G27: Rishabh | H27: On | I27: 46112 | J27: No
A28: =A27+1 -> 23 | B28: Prop | C28: Affluence Prop | D28: Affluence Prop - Profit and Loss | E28: Debt | F28: =5906672.74+-1197579 -> 4709093.7 | G28: Rishabh | H28: On | I28: 46108 | J28: No
A29: =A28+1 -> 24 | B29: Prop | C29: Affluence High Risk | D29: Affluence High Risk - Deposit | E29: Debt | F29: 0 | G29: Rishabh | H29: On | I29: 46112 | J29: No
A30: =A29+1 -> 25 | B30: Prop | C30: Affluence High Risk | D30: Affluence High Risk - Profit and Loss | E30: Debt | F30: =746770.22+1108983.82+2872822.57+6375938*30%*35% -> 5398050.1 | G30: Rishabh | H30: On | I30: 46112 | J30: No
A31: =A30+1 -> 26 | B31: Prop | C31: Ashika Prop | D31: Ashika Prop - Deposit | E31: Debt | F31: 0 | G31: Rishabh | H31: On | I31: 46112 | J31: No
A32: =A31+1 -> 27 | B32: Prop | C32: Ashika Prop | D32: Ashika Prop - Profit and Loss | E32: Debt | F32: =393914.3+-20567.7+(81218+90278)*20%*35% -> 385351.32 | G32: Rishabh | H32: On | I32: 46112 | J32: No
A33: =A32+1 -> 28 | B33: Prop | C33: SRE | D33: Deposit | E33: Debt | F33: 2500000 | G33: Rishabh | H33: On | I33: 46112 | J33: No
A34: =A33+1 -> 29 | B34: Prop | C34: SRE | D34: Profit and Loss | E34: Debt | F34: =-2499611.53+(22991024.73-6966176.5)*60% -> 7115297.4 | G34: Rishabh | H34: Off | I34: 46112 | J34: No
A35: =A34+1 -> 30 | B35: Prop | C35: Jainam FPI | D35: Deposit | E35: Debt | F35: 10000000 | G35: Rishabh | H35: Off | I35: 46112 | J35: No
A36: =A35+1 -> 31 | B36: Prop | C36: Jainam FPI | D36: Profit and Loss | E36: Debt | F36: 0 | G36: Rishabh | H36: Off | I36: 46112 | J36: No
A37: =A36+1 -> 32 | B37: Prop | C37: Rishabh Jainam Prop | D37: Profit and Loss | E37: Debt | F37: 17236946 | G37: Rishabh | H37: Off | I37: 46112 | J37: No
A39: =A37+1 -> 33 | B39: Other Investments | C39: Sushila Nahar Equity MF | D39: Sushila Nahar Equity MF | E39: Equity | F39: 15014887 | G39: Rishabh | H39: On | I39: 46112 | J39: No
A40: =A39+1 -> 34 | B40: Other Investments | C40: Yogita Agrawal Qode PMS | D40: Yogita Agrawal Qode PMS - QMF | E40: Equity | F40: 10279400 | G40: Rishabh | H40: On | I40: 46112 | J40: No
A41: =A40+1 -> 35 | B41: Other Investments | C41: Yogita Agrawal Qode PMS | D41: Yogita Agrawal Qode PMS - QTF | E41: Equity | F41: 5349685.4 | G41: Rishabh | H41: On | I41: 46112 | J41: No
A42: =A41+1 -> 36 | B42: Other Investments | C42: Yogita Agrawal Qode PMS | D42: Yogita Agrawal Qode PMS - QAW | E42: Equity | F42: 23981288 | G42: Rishabh | H42: On | I42: 46112 | J42: No
A43: =A42+1 -> 37 | B43: Other Investments | C43: Loan to Vihaan | D43: Loan to Vihaan | E43: Debt | F43: 3000000 | G43: Rishabh | H43: On | I43: 46112 | J43: No
A44: =A43+1 -> 38 | B44: Other Investments | C44: Rishabh Nahar Qode PMS | D44: Rishabh Nahar Qode PMS - QFH | E44: Equity | F44: 5687110 | G44: Rishabh | H44: On | I44: 46112 | J44: No
...

Sheet Cash and Margin
A1: Total Exposure in Mishayan for Long & Psar: | J1: Inputs: | P1: Cash and Non Cash Component | Z1: Mishayan | AC1: Rishabh
Z2: Current Cash in Mishayan | AA2: =U5 -> 2.7724849e+08 | AC2: Cash in Zerodha | AD2: ='Networth Inputs'!F9+'Networth Inputs'!F10 -> 1014842.1
A3: Sr. No. | B3: Particulars | C3: Value | E3: Sr. No. | F3: Particulars | G3: Value | J3: Sr. No. | K3: Particulars | L3: Input | P3: Sr. No. | Q3: System | R3: Cash Component (Liquid Funds) | S3: Non Cash Component | T3: Liquidcase | U3: Cash | V3: Total | W3: Total % of PV | Z3: Buy Debt mutual fund | AA3: =-R7/0.9 -> 20707981 | AC3: Cash in Bank | AD3: 5000000
A4: 1 | B4: Zerodha Broking RN | C4: =SUM('Networth Inputs'!F4:F10) -> 2.3755056e+08 | E4: 1 | F4: Current Gold Exposure | G4: =21*100*147666 -> 310098600 | J4: 1 | K4: Long Options PS | L4: 0.015 | Z4: Buy Liquidcase | AA4: =-T7 -> 11956746 | AC4: Jainam Deposit | AD4: 31500000
A5: =A4+1 -> 2 | B5: Zerodha Broking Mishayan | C5: =SUM('Networth Inputs'!F12:F18) -> 3.9263752e+08 | E5: =E4+1 -> 2 | F5: Ideal Gold Exposure | G5: =SUMIFS('Networth Inputs'!$F$4:$F$18,'Networth Inputs'!$E$4:$E$18,"Debt")+SUMIFS('Networth Inputs'!$F$39:$F$94,'Networth Inputs'!$E$39:$E$94,"Debt") -> 1.5020531e+08 | H5: based on debt | J5: =J4+1 -> 2 | K5: PSAR Multiplier | L5: 2.1 | P5: 1 | Q5: Available on Zerodha | R5: =101363742-0.94*T5 -> 101363742 | S5: 0 | T5: =VLOOKUP("Zerodha Broking Mishayan: Liquidbees/ Liquidcase",'Networth Inputs - old'!$C$4:$E$114,3,FALSE) -> 0 | U5: ='Networth Inputs'!F17+'Networth Inputs'!F18 -> 2.7724849e+08 | V5: =SUM(R5:U5) -> 3.7861223e+08 | W5: =V5/$C$22 -> 0.5277526 | Z5: Keep Cash | AA5: =U6 -> 43996263 | AC5: Mishayan Loan Repayment | AD5: =50000000-31500000 -> 18500000
A6: =A5+1 -> 3 | B6: ='Networth Inputs'!D39 -> Sushila Nahar Equity MF | C6: ='Networth Inputs'!F39 -> 15014887 | E6: =E5+1 -> 3 | F6: Put Protection Exposure | G6: =SUMIFS('Networth Inputs'!$F$4:$F$18,'Networth Inputs'!$E$4:$E$18,"Equity") -> 2.3304248e+08 | H6: equities in zerodha | J6: =J5+1 -> 3 | K6: Psar Leverage | L6: 8 | P6: =P5+1 -> 2 | Q6: Total Required | R6: =SUM(R9:R16) -> 1.2000092e+08 | S6: =SUM(S9:S16) -> 1.2000092e+08 | T6: =SUM(T9:T16) -> 11956746 | U6: =SUM(U9:U16) -> 43996263 | V6: =SUM(V9:V16) -> 2.9595486e+08 | W6: =V6/$C$22 -> 0.4125354 | Z6: Balance Cash Available | AA6: =AA2-AA3-AA4-AA5 -> 2.005875e+08 | AC6: Cash Available to deploy in Equity | AD6: =SUM(AD2:AD5) -> 56014842
A7: =A6+1 -> 4 | B7: ='Networth Inputs'!D40 -> Yogita Agrawal Qode PMS - QMF | C7: ='Networth Inputs'!F40 -> 10279400 | J7: =J6+1 -> 4 | K7: Cash Drawdown Margin | L7: =5%*2/3 -> 0.033333333 | P7: =P6+1 -> 3 | Q7: Margin Excess/Shortfall | R7: =R5-R6 -> -18637183 | S7: =S5-S6 -> -1.2000092e+08 | T7: =T5-T6 -> -11956746 | U7: =U5-U6 -> 2.3325223e+08 | V7: =SUM(R7:U7) -> 82657373 | W7: =V7/$C$22 -> 0.11521721 | Z7: Reverse loan to RN | AA7: =50000000-31500000 -> 18500000
A8: =A7+1 -> 5 | B8: ='Networth Inputs'!D43 -> Loan to Vihaan | C8: ='Networth Inputs'!F43 -> 3000000 | J8: =J7+1 -> 5 | K8: Liquidbees Drawdown Margin | L8: =5%*1/3 -> 0.016666667 | Z8: Outstanding OD - Actual | AA8: 65000000
A9: =A8+1 -> 6 | B9: ='Networth Inputs'!D44 -> Rishabh Nahar Qode PMS - QFH | C9: ='Networth Inputs'!F44 -> 5687110 | J9: =J8+1 -> 6 | K9: DMA Cash Requirement | L9: 0.04 | P9: 1 | Q9: Cash Drawdown Margin | U9: =L7*C22 -> 23913492 | V9: =SUM(R9:U9) -> 23913492 | W9: =V9/$C$22 -> 0.033333333 | Z9: Currently Payback OD | AA9: =32500000-4400000 -> 28100000
A10: =A9+1 -> 7 | B10: ='Networth Inputs'!D45 -> Swan Capital | C10: ='Networth Inputs'!F45 -> 5881036 | J10: =J9+1 -> 7 | K10: Gold Fut Leverage | L10: 6 | P10: =P9+1 -> 2 | Q10: Liquidbees Drawdown Margin | T10: =L8*C22 -> 11956746 | V10: =SUM(R10:U10) -> 11956746 | W10: =V10/$C$22 -> 0.016666667 | Z10: Expenses | AA10: 6000000
A11: =A10+1 -> 8 | B11: ='Networth Inputs'!D46 -> Sushila Nahar HDFC | C11: ='Networth Inputs'!F46 -> 0 | J11: =J10+1 -> 8 | Z11: Cash Available to deploy in Equity | AA11: =AA6-AA7-AA9-AA10 -> 1.479875e+08
A12: =A11+1 -> 9 | B12: ='Networth Inputs'!D47 -> Sushila Nahar Zerodha | C12: ='Networth Inputs'!F47 -> 11699620 | J12: =J11+1 -> 9 | P12: 1 | Q12: Long Options | U12: =L4*C22 -> 10761071 | V12: =SUM(R12:U12) -> 10761071 | W12: =V12/$C$22 -> 0.015
A13: =A12+1 -> 10 | B13: ='Networth Inputs'!D49 -> HDFC Bank RN | C13: ='Networth Inputs'!F49 -> 5898983 | J13: =J12+1 -> 10 | P13: =P12+1 -> 2 | Q13: PSAR | R13: =$C$22*$L$5/$L$6/2 -> 94159375 | S13: =$C$22*$L$5/$L$6/2 -> 94159375 | V13: =SUM(R13:U13) -> 1.8831875e+08 | W13: =V13/$C$22 -> 0.2625
A14: =A13+1 -> 11 | B14: ='Networth Inputs'!D50 -> HDFC Bank Mishayan | C14: ='Networth Inputs'!F50 -> 1857193 | P14: =P13+1 -> 3 | Q14: DMA | U14: =$L$9*G6 -> 9321699 | V14: =SUM(R14:U14) -> 9321699 | W14: =V14/$C$22 -> 0.01299364 | Z14: note: if expenses increase reduce od repayment amount
A15: =A14+1 -> 12 | B15: ='Networth Inputs'!D51 -> FD | C15: ='Networth Inputs'!F51 -> 23500000 | P15: =P14+1 -> 4 | Q15: Gold Fut | R15: =$G$4/$L$10/2 -> 25841550 | S15: =$G$4/$L$10/2 -> 25841550 | V15: =SUM(R15:U15) -> 51683100 | W15: =V15/$C$22 -> 0.072041758
A16: =A15+1 -> 13 | B16: ='Networth Inputs'!D52 -> ICICI Bank OD | C16: ='Networth Inputs'!F52 -> 898458
A17: =A16+1 -> 14 | B17: ='Networth Inputs'!D53 -> HDFC Bank FD | C17: ='Networth Inputs'!F53 -> 1000000 | J17: Note: | K17: Cash + DD Margin for 3x psar is 15%
A18: =A17+1 -> 15 | B18: ='Networth Inputs'!D55 -> Sumesh FD | C18: ='Networth Inputs'!F55 -> 2500000 | K18: Cash + DD Margin for 2x psar is 5%
